{"timestamp": "2024-06-08  08:25:55", "level": "ERROR", "name": "error_info", "message": "Unknown Exception", "exc_info": "Traceback (most recent call last):\n  File \"G:\\GIT\\Code-Wars-solutions\\app\\kyu_4\\router.py\", line 181, in hamming\n    raise TimeoutError\nTimeoutError", "number": 5}
{"timestamp": "2024-06-08  08:32:27", "level": "ERROR", "name": "error_info", "message": "Unknown Exception", "exc_info": "Traceback (most recent call last):\n  File \"G:\\GIT\\Code-Wars-solutions\\app\\kyu_4\\router.py\", line 185, in hamming\n    raise TimeoutError\nTimeoutError", "number": 5}
